STARTED JOB AT: Mon Jan 16 20:53:05 EST 2023

2023-01-16 20:53:08.370388 (reading meta data, all rows)
2023-01-16 20:59:48.094424 (done reading meta data, 238803125 rows)
2023-01-16 21:01:42.937228, on 140000000 - 160000000
Exception in thread Thread-1:
Traceback (most recent call last):
  File "/n/sw/eb/apps/centos7/Anaconda3/2022.05/lib/python3.9/threading.py", line 973, in _bootstrap_inner
    self.run()
  File "/n/sw/eb/apps/centos7/Anaconda3/2022.05/lib/python3.9/threading.py", line 910, in run
    self._target(*self._args, **self._kwargs)
  File "/n/sw/eb/apps/centos7/Anaconda3/2022.05/lib/python3.9/multiprocessing/pool.py", line 513, in _handle_workers
    cls._maintain_pool(ctx, Process, processes, pool, inqueue,
  File "/n/sw/eb/apps/centos7/Anaconda3/2022.05/lib/python3.9/multiprocessing/pool.py", line 337, in _maintain_pool
    Pool._repopulate_pool_static(ctx, Process, processes, pool,
  File "/n/sw/eb/apps/centos7/Anaconda3/2022.05/lib/python3.9/multiprocessing/pool.py", line 326, in _repopulate_pool_static
    w.start()
  File "/n/sw/eb/apps/centos7/Anaconda3/2022.05/lib/python3.9/multiprocessing/process.py", line 121, in start
    self._popen = self._Popen(self)
  File "/n/sw/eb/apps/centos7/Anaconda3/2022.05/lib/python3.9/multiprocessing/context.py", line 277, in _Popen
    return Popen(process_obj)
  File "/n/sw/eb/apps/centos7/Anaconda3/2022.05/lib/python3.9/multiprocessing/popen_fork.py", line 19, in __init__
    self._launch(process_obj)
  File "/n/sw/eb/apps/centos7/Anaconda3/2022.05/lib/python3.9/multiprocessing/popen_fork.py", line 66, in _launch
    self.pid = os.fork()
OSError: [Errno 12] Cannot allocate memory
Process ForkPoolWorker-7:
Traceback (most recent call last):
  File "/n/sw/eb/apps/centos7/Anaconda3/2022.05/lib/python3.9/multiprocessing/pool.py", line 131, in worker
    put((job, i, result))
  File "/n/sw/eb/apps/centos7/Anaconda3/2022.05/lib/python3.9/multiprocessing/queues.py", line 372, in put
    obj = _ForkingPickler.dumps(obj)
  File "/n/sw/eb/apps/centos7/Anaconda3/2022.05/lib/python3.9/multiprocessing/reduction.py", line 51, in dumps
    cls(buf, protocol).dump(obj)
MemoryError

During handling of the above exception, another exception occurred:

Traceback (most recent call last):
  File "/n/sw/eb/apps/centos7/Anaconda3/2022.05/lib/python3.9/multiprocessing/process.py", line 315, in _bootstrap
    self.run()
  File "/n/sw/eb/apps/centos7/Anaconda3/2022.05/lib/python3.9/multiprocessing/process.py", line 108, in run
    self._target(*self._args, **self._kwargs)
  File "/n/sw/eb/apps/centos7/Anaconda3/2022.05/lib/python3.9/multiprocessing/pool.py", line 134, in worker
    util.debug("Possible encoding error while sending result: %s" % (
  File "/n/sw/eb/apps/centos7/Anaconda3/2022.05/lib/python3.9/multiprocessing/pool.py", line 90, in __str__
    return "Error sending result: '%s'. Reason: '%s'" % (self.value,
MemoryError
Process ForkPoolWorker-18:
Traceback (most recent call last):
  File "/n/sw/eb/apps/centos7/Anaconda3/2022.05/lib/python3.9/multiprocessing/pool.py", line 131, in worker
    put((job, i, result))
  File "/n/sw/eb/apps/centos7/Anaconda3/2022.05/lib/python3.9/multiprocessing/queues.py", line 372, in put
    obj = _ForkingPickler.dumps(obj)
  File "/n/sw/eb/apps/centos7/Anaconda3/2022.05/lib/python3.9/multiprocessing/reduction.py", line 51, in dumps
    cls(buf, protocol).dump(obj)
MemoryError

During handling of the above exception, another exception occurred:

Traceback (most recent call last):
  File "/n/sw/eb/apps/centos7/Anaconda3/2022.05/lib/python3.9/multiprocessing/process.py", line 315, in _bootstrap
    self.run()
  File "/n/sw/eb/apps/centos7/Anaconda3/2022.05/lib/python3.9/multiprocessing/process.py", line 108, in run
    self._target(*self._args, **self._kwargs)
  File "/n/sw/eb/apps/centos7/Anaconda3/2022.05/lib/python3.9/multiprocessing/pool.py", line 134, in worker
    util.debug("Possible encoding error while sending result: %s" % (
MemoryError
slurmstepd: error: *** JOB 39238185 ON holy7c26409 CANCELLED AT 2023-01-17T00:38:56 ***
